Thu Oct 28 17:58:47 CST 2021 : Apache Derby Network Server - 10.14.2.0 - (1828579) started and ready to accept connections on port 1527
----------------------------------------------------------------
Thu Oct 28 17:58:48 CST 2021:
Booting Derby version The Apache Software Foundation - Apache Derby - 10.14.2.0 - (1828579): instance a816c00e-017c-c957-818a-ffffa366e679 
on database directory C:\Users\Freis\Documents\Repositories\Séptimo Cuatrimestre\Estructuras de Datos\Proyecto_Final\Proyecto-Estructuras-De-Datos\DATABASES\Proyecto_Estructuras with class loader jdk.internal.loader.ClassLoaders$AppClassLoader@c387f44 
Loaded from file:/C:/Users/Freis/Documents/db-derby-10.14.2.0-bin/lib/derby.jar
java.vendor=Oracle Corporation
java.runtime.version=14.0.2+12-46
user.dir=C:\Users\Freis\Documents\db-derby-10.14.2.0-bin
os.name=Windows 10
os.arch=amd64
os.version=10.0
derby.system.home=C:\Users\Freis\Documents\Repositories\Séptimo Cuatrimestre\Estructuras de Datos\Proyecto_Final\Proyecto-Estructuras-De-Datos\DATABASES
Database Class Loader started - derby.database.classpath=''
Thu Oct 28 17:58:48 CST 2021 Thread[DRDAConnThread_2,5,main] (XID = 670), (SESSIONID = 0), (DATABASE = Proyecto_Estructuras), (DRDAID = {1}), Cleanup action starting
java.sql.SQLNonTransientConnectionException: Connection authentication failure occurred.  Reason: Invalid authentication..
	at org.apache.derby.impl.jdbc.SQLExceptionFactory.getSQLException(Unknown Source)
	at org.apache.derby.impl.jdbc.SQLExceptionFactory.getSQLException(Unknown Source)
	at org.apache.derby.impl.jdbc.Util.generateCsSQLException(Unknown Source)
	at org.apache.derby.impl.jdbc.Util.generateCsSQLException(Unknown Source)
	at org.apache.derby.impl.jdbc.EmbedConnection.newSQLException(Unknown Source)
	at org.apache.derby.impl.jdbc.EmbedConnection.checkUserCredentials(Unknown Source)
	at org.apache.derby.impl.jdbc.EmbedConnection.<init>(Unknown Source)
	at org.apache.derby.jdbc.InternalDriver$1.run(Unknown Source)
	at org.apache.derby.jdbc.InternalDriver$1.run(Unknown Source)
	at java.base/java.security.AccessController.doPrivileged(AccessController.java:554)
	at org.apache.derby.jdbc.InternalDriver.getNewEmbedConnection(Unknown Source)
	at org.apache.derby.jdbc.InternalDriver.connect(Unknown Source)
	at org.apache.derby.jdbc.InternalDriver.connect(Unknown Source)
	at org.apache.derby.jdbc.EmbeddedDriver.connect(Unknown Source)
	at org.apache.derby.impl.drda.Database.makeConnection(Unknown Source)
	at org.apache.derby.impl.drda.DRDAConnThread.getConnFromDatabaseName(Unknown Source)
	at org.apache.derby.impl.drda.DRDAConnThread.verifyUserIdPassword(Unknown Source)
	at org.apache.derby.impl.drda.DRDAConnThread.parseSECCHK(Unknown Source)
	at org.apache.derby.impl.drda.DRDAConnThread.parseDRDAConnection(Unknown Source)
	at org.apache.derby.impl.drda.DRDAConnThread.processCommands(Unknown Source)
	at org.apache.derby.impl.drda.DRDAConnThread.run(Unknown Source)
Caused by: ERROR 08004: Connection authentication failure occurred.  Reason: Invalid authentication..
	at org.apache.derby.iapi.error.StandardException.newException(Unknown Source)
	at org.apache.derby.impl.jdbc.SQLExceptionFactory.wrapArgsForTransportAcrossDRDA(Unknown Source)
	... 21 more
============= begin nested exception, level (1) ===========
ERROR 08004: Connection authentication failure occurred.  Reason: Invalid authentication..
	at org.apache.derby.iapi.error.StandardException.newException(Unknown Source)
	at org.apache.derby.impl.jdbc.SQLExceptionFactory.wrapArgsForTransportAcrossDRDA(Unknown Source)
	at org.apache.derby.impl.jdbc.SQLExceptionFactory.getSQLException(Unknown Source)
	at org.apache.derby.impl.jdbc.SQLExceptionFactory.getSQLException(Unknown Source)
	at org.apache.derby.impl.jdbc.Util.generateCsSQLException(Unknown Source)
	at org.apache.derby.impl.jdbc.Util.generateCsSQLException(Unknown Source)
	at org.apache.derby.impl.jdbc.EmbedConnection.newSQLException(Unknown Source)
	at org.apache.derby.impl.jdbc.EmbedConnection.checkUserCredentials(Unknown Source)
	at org.apache.derby.impl.jdbc.EmbedConnection.<init>(Unknown Source)
	at org.apache.derby.jdbc.InternalDriver$1.run(Unknown Source)
	at org.apache.derby.jdbc.InternalDriver$1.run(Unknown Source)
	at java.base/java.security.AccessController.doPrivileged(AccessController.java:554)
	at org.apache.derby.jdbc.InternalDriver.getNewEmbedConnection(Unknown Source)
	at org.apache.derby.jdbc.InternalDriver.connect(Unknown Source)
	at org.apache.derby.jdbc.InternalDriver.connect(Unknown Source)
	at org.apache.derby.jdbc.EmbeddedDriver.connect(Unknown Source)
	at org.apache.derby.impl.drda.Database.makeConnection(Unknown Source)
	at org.apache.derby.impl.drda.DRDAConnThread.getConnFromDatabaseName(Unknown Source)
	at org.apache.derby.impl.drda.DRDAConnThread.verifyUserIdPassword(Unknown Source)
	at org.apache.derby.impl.drda.DRDAConnThread.parseSECCHK(Unknown Source)
	at org.apache.derby.impl.drda.DRDAConnThread.parseDRDAConnection(Unknown Source)
	at org.apache.derby.impl.drda.DRDAConnThread.processCommands(Unknown Source)
	at org.apache.derby.impl.drda.DRDAConnThread.run(Unknown Source)
============= end nested exception, level (1) ===========
Cleanup action completed
Thu Oct 28 17:58:48 CST 2021 Thread[DRDAConnThread_2,5,main] (DATABASE = Proyecto_Estructuras), (DRDAID = {1}), Connection authentication failure occurred.  Reason: Invalid authentication..
